<?xml version="1.0"?>
<robot name="my_robot" xmlns:xacro="http://www.ros.org/wiki/xacro">
    <xacro:include filename="$(find my_robot)/urdf/my_robot.gazebo" />

    <link name="robot_footprint"></link>

    <joint name="robot_footprint_joint" type="fixed">
        <origin xyz="0 0 0" rpy="0 0 0" />
        <parent link="robot_footprint" />
        <child link="chassis" />
    </joint>

    <link name="chassis">
        <pose>0 0 0.1 0 0 0</pose>

        <inertial>
            <mass value="15.0" />
            <origin xyz="0.0 0 0" rpy=" 0 0 0" />
            <inertia ixx="0.1" ixy="0" ixz="0" iyy="0.1" iyz="0" izz="0.1" />
        </inertial>

        <collision name="collision">
            <origin xyz="0 0 0" rpy=" 0 0 0" />
            <geometry>
                <box size=".4 .2 .1" />
            </geometry>
        </collision>

        <visual name="chassis_visual">
            <origin xyz="0 0 0" rpy=" 0 0 0" />
            <geometry>
                <box size=".4 .2 .1" />
            </geometry>
        </visual>
    </link>

    <link name="front_left_wheel">
        <inertial>
            <mass value="5.0" />
            <origin xyz="0 0 0" rpy="0 1.5707 1.5707" />
            <inertia ixx="0.1" ixy="0" ixz="0" iyy="0.1" iyz="0" izz="0.1" />
        </inertial>

        <collision name="front_left_wheel_collision">
            <origin xyz="0 0 0" rpy="0 1.5707 1.5707" />
            <geometry>
                <cylinder radius="0.1" length="0.049" />
            </geometry>
            <surface>
                <!-- Copied from Pioneer 3AT -->
                <contact>
                    <ode>
                        <kp>1e+06</kp>
                        <kd>100</kd>
                        <max_vel>1</max_vel>
                        <min_depth>0</min_depth>
                    </ode>
                </contact>
                <friction>
                    <ode>
                        <mu>1</mu>
                        <mu2>1</mu2>
                        <fdir1>0 1 0</fdir1>
                    </ode>
                </friction>
            </surface>
        </collision>

        <visual name="front_left_wheel_visual">
            <origin xyz="0 0 0" rpy="0 1.5707 1.5707" />
            <geometry>
                <cylinder radius="0.1" length="0.049" />
            </geometry>
        </visual>
    </link>

    <link name="back_left_wheel">
        <inertial>
            <mass value="5.0" />
            <origin xyz="0 0 0" rpy="0 1.5707 1.5707" />
            <inertia ixx="0.1" ixy="0" ixz="0" iyy="0.1" iyz="0" izz="0.1" />
        </inertial>

        <collision name="back_left_wheel_collision">
            <origin xyz="0 0 0" rpy="0 1.5707 1.5707" />
            <geometry>
                <cylinder radius="0.1" length="0.049" />
            </geometry>
            <surface>
                <!-- Copied from Pioneer 3AT -->
                <contact>
                    <ode>
                        <kp>1e+06</kp>
                        <kd>100</kd>
                        <max_vel>1</max_vel>
                        <min_depth>0</min_depth>
                    </ode>
                </contact>
                <friction>
                    <ode>
                        <mu>1</mu>
                        <mu2>1</mu2>
                        <fdir1>0 1 0</fdir1>
                    </ode>
                </friction>
            </surface>
        </collision>

        <visual name="back_left_wheel_visual">
            <origin xyz="0 0 0" rpy="0 1.5707 1.5707" />
            <geometry>
                <cylinder radius="0.1" length="0.049" />
            </geometry>
        </visual>
    </link>

    <link name="front_right_wheel">
        <inertial>
            <mass value="5.0" />
            <origin xyz="0 0 0" rpy="0 1.5707 1.5707" />
            <inertia ixx="0.1" ixy="0" ixz="0" iyy="0.1" iyz="0" izz="0.1" />
        </inertial>

        <collision name="front_right_wheel_collision">
            <origin xyz="0 0 0" rpy="0 1.5707 1.5707" />
            <geometry>
                <cylinder radius="0.1" length="0.049" />
            </geometry>
            <surface>
                <!-- Copied from Pioneer 3AT -->
                <contact>
                    <ode>
                        <kp>1e+06</kp>
                        <kd>100</kd>
                        <max_vel>1</max_vel>
                        <min_depth>0</min_depth>
                    </ode>
                </contact>
                <friction>
                    <ode>
                        <mu>1</mu>
                        <mu2>1</mu2>
                        <fdir1>0 1 0</fdir1>
                    </ode>
                </friction>
            </surface>
        </collision>

        <visual name="front_right_wheel_visual">
            <origin xyz="0 0 0" rpy="0 1.5707 1.5707" />
            <geometry>
                <cylinder radius="0.1" length="0.049" />
            </geometry>
        </visual>
    </link>

    <link name="back_right_wheel">
        <inertial>
            <mass value="5.0" />
            <origin xyz="0 0 0" rpy="0 1.5707 1.5707" />
            <inertia ixx="0.1" ixy="0" ixz="0" iyy="0.1" iyz="0" izz="0.1" />
        </inertial>

        <collision name="back_right_wheel_collision">
            <origin xyz="0 0 0" rpy="0 1.5707 1.5707" />
            <geometry>
                <cylinder radius="0.1" length="0.049" />
            </geometry>
            <surface>
                <!-- Copied from Pioneer 3AT -->
                <contact>
                    <ode>
                        <kp>1e+06</kp>
                        <kd>100</kd>
                        <max_vel>1</max_vel>
                        <min_depth>0</min_depth>
                    </ode>
                </contact>
                <friction>
                    <ode>
                        <mu>1</mu>
                        <mu2>1</mu2>
                        <fdir1>0 1 0</fdir1>
                    </ode>
                </friction>
            </surface>
        </collision>

        <visual name="back_right_wheel_visual">
            <origin xyz="0 0 0" rpy="0 1.5707 1.5707" />
            <geometry>
                <cylinder radius="0.1" length="0.049" />
            </geometry>
        </visual>
    </link>

    <joint type="continuous" name="front_left_wheel_hinge">
        <origin xyz="0.15 0.15 0" rpy="0 0 0" />
        <child link="front_left_wheel" />
        <parent link="chassis" />
        <axis xyz="0 1 0" rpy="0 0 0" />
        <limit effort="10000" velocity="1000" />
        <dynamics damping="1.0" friction="1.0" />
    </joint>

    <joint type="continuous" name="back_left_wheel_hinge">
        <origin xyz="-0.15 0.15 0" rpy="0 0 0" />
        <child link="back_left_wheel" />
        <parent link="chassis" />
        <axis xyz="0 1 0" rpy="0 0 0" />
        <limit effort="10000" velocity="1000" />
        <dynamics damping="1.0" friction="1.0" />
    </joint>

    <joint type="continuous" name="front_right_wheel_hinge">
        <origin xyz="0.15 -0.15 0" rpy="0 0 0" />
        <child link="front_right_wheel" />
        <parent link="chassis" />
        <axis xyz="0 1 0" rpy="0 0 0" />
        <limit effort="10000" velocity="1000" />
        <dynamics damping="1.0" friction="1.0" />
    </joint>

    <joint type="continuous" name="back_right_wheel_hinge">
        <origin xyz="-0.15 -0.15 0" rpy="0 0 0" />
        <child link="back_right_wheel" />
        <parent link="chassis" />
        <axis xyz="0 1 0" rpy="0 0 0" />
        <limit effort="10000" velocity="1000" />
        <dynamics damping="1.0" friction="1.0" />
    </joint>

    <link name="camera">
        <inertial>
            <mass value="0.1" />
            <origin xyz="0 0 0" rpy="0 0 0" />
            <inertia ixx="1e-6" ixy="0" ixz="0" iyy="1e-6" iyz="0" izz="1e-6" />
        </inertial>

        <collision name="camera_collision">
            <origin xyz="0 0 0" rpy="0 0 0" />
            <geometry>
                <box size="0.05 0.05 0.05" />
            </geometry>
        </collision>

        <visual name="camera_visual">
            <origin xyz="0 0 0" rpy="0 0 0" />
            <geometry>
                <box size="0.05 0.05 0.05" />
            </geometry>
        </visual>
    </link>

    <joint type="fixed" name="camera_joint">
        <origin xyz="0.2 0 0" rpy="0 0 0" />
        <child link="camera" />
        <parent link="chassis" />
        <axis xyz="0 1 0" rpy="0 0 0" />
        <limit effort="10000" velocity="1000" />
        <dynamics damping="1.0" friction="1.0" />
    </joint>

    <link name="hokuyo">
        <inertial>
            <mass value="1e-5" />
            <origin xyz="0 0 0" rpy="0 0 0" />
            <inertia ixx="1e-6" ixy="0" ixz="0" iyy="1e-6" iyz="0" izz="1e-6" />
        </inertial>

        <collision name="hokuyo_collision">
            <origin xyz="0 0 0" rpy="0 0 0" />
            <geometry>
                <box size="0.1 0.1 0.1" />
            </geometry>
        </collision>

        <visual name="hokuyo_visual">
            <origin xyz="0 0 0" rpy="0 0 0" />
            <geometry>
                <mesh filename="package://my_robot/meshes/hokuyo.dae" />
            </geometry>
        </visual>
    </link>

    <joint type="fixed" name="hokuyo_joint">
        <origin xyz="0.15 0 0.1" rpy="0 0 0" />
        <child link="hokuyo" />
        <parent link="chassis" />
        <axis xyz="0 1 0" rpy="0 0 0" />
        <limit effort="10000" velocity="1000" />
        <dynamics damping="1.0" friction="1.0" />
    </joint>

    <gazebo reference="left_wheel">
        <material>Gazebo/Black</material>
    </gazebo>

    <gazebo reference="right_wheel">
        <material>Gazebo/Black</material>
    </gazebo>

    <gazebo reference="chassis">
        <material>Gazebo/RedTransparent</material>
    </gazebo>

    <gazebo reference="camera">
        <material>Gazebo/DarkGrey</material>
    </gazebo>

    <gazebo reference="hokuyo">
        <material>Gazebo/LightBlueLaser</material>
    </gazebo>

</robot>